<?xml version="1.0" ?>
<robot name="ur5">
    <link name="base_link">
        <visual>
            <geometry>
                <mesh filename="package://ur5_description/meshes/ur5/visual/base.dae" />
            </geometry>
            <material name="LightGrey">
                <color rgba="0.7 0.7 0.7 1.0" />
            </material>
        </visual>
        <collision>
            <geometry>
                <mesh filename="package://ur5_description/meshes/ur5/collision/base.stl" />
            </geometry>
        </collision>
        <inertial>
            <mass value="4.0" />
            <origin rpy="0 0 0" xyz="0.0 0.0 0.0" />
            <inertia ixx="0.00443333156" ixy="0.0" ixz="0.0" iyy="0.00443333156" iyz="0.0" izz="0.0072" />
        </inertial>
    </link>
    <joint name="shoulder_pan_joint" type="revolute">
        <parent link="base_link" />
        <child link="shoulder_link" />
        <origin rpy="0.0 0.0 0.0" xyz="0.0 0.0 0.089159" />
        <axis xyz="0 0 1" />
        <limit effort="150.0" lower="-3.141592653589793" upper="3.141592653589793" velocity="3.15" />
        <dynamics damping="0.0" friction="0.0" />
    </joint>
    <link name="shoulder_link">
        <visual>
            <geometry>
                <mesh filename="package://ur5_description/meshes/ur5/visual/shoulder.dae" />
            </geometry>
            <material name="LightGrey">
                <color rgba="0.7 0.7 0.7 1.0" />
            </material>
        </visual>
        <collision>
            <geometry>
                <mesh filename="package://ur5_description/meshes/ur5/collision/shoulder.stl" />
            </geometry>
        </collision>
        <inertial>
            <mass value="3.7" />
            <origin rpy="0 0 0" xyz="0.0 0.0 0.0" />
            <inertia ixx="0.010267495893" ixy="0.0" ixz="0.0" iyy="0.010267495893" iyz="0.0" izz="0.00666" />
        </inertial>
    </link>
    <joint name="shoulder_lift_joint" type="revolute">
        <parent link="shoulder_link" />
        <child link="upper_arm_link" />
        <origin rpy="0.0 1.5707963267948966 0.0" xyz="0.0 0.13585 0.0" />
        <axis xyz="0 1 0" />
        <limit effort="150.0" lower="-3.141592653589793" upper="3.141592653589793" velocity="3.15" />
        <dynamics damping="0.0" friction="0.0" />
    </joint>
    <link name="upper_arm_link">
        <visual>
            <geometry>
                <mesh filename="package://ur5_description/meshes/ur5/visual/upperarm.dae" />
            </geometry>
            <material name="LightGrey">
                <color rgba="0.7 0.7 0.7 1.0" />
            </material>
        </visual>
        <collision>
            <geometry>
                <mesh filename="package://ur5_description/meshes/ur5/collision/upperarm.stl" />
            </geometry>
        </collision>
        <inertial>
            <mass value="8.393" />
            <origin rpy="0 0 0" xyz="0.0 0.0 0.28" />
            <inertia ixx="0.22689067591036005" ixy="0.0" ixz="0.0" iyy="0.22689067591036005" iyz="0.0" izz="0.0151074" />
        </inertial>
    </link>
    <joint name="elbow_joint" type="revolute">
        <parent link="upper_arm_link" />
        <child link="forearm_link" />
        <origin rpy="0.0 0.0 0.0" xyz="0.0 -0.1197 0.425" />
        <axis xyz="0 1 0" />
        <limit effort="150.0" lower="-3.141592653589793" upper="3.141592653589793" velocity="3.15" />
        <dynamics damping="0.0" friction="0.0" />
    </joint>
    <link name="forearm_link">
        <visual>
            <geometry>
                <mesh filename="package://ur5_description/meshes/ur5/visual/forearm.dae" />
            </geometry>
            <material name="LightGrey">
                <color rgba="0.7 0.7 0.7 1.0" />
            </material>
        </visual>
        <collision>
            <geometry>
                <mesh filename="package://ur5_description/meshes/ur5/collision/forearm.stl" />
            </geometry>
        </collision>
        <inertial>
            <mass value="2.275" />
            <origin rpy="0 0 0" xyz="0.0 0.0 0.25" />
            <inertia ixx="0.04944331355599999" ixy="0.0" ixz="0.0" iyy="0.04944331355599999" iyz="0.0" izz="0.004095" />
        </inertial>
    </link>
    <joint name="wrist_1_joint" type="revolute">
        <parent link="forearm_link" />
        <child link="wrist_1_link" />
        <origin rpy="0.0 1.5707963267948966 0.0" xyz="0.0 0.0 0.39225" />
        <axis xyz="0 1 0" />
        <limit effort="28.0" lower="-3.141592653589793" upper="3.141592653589793" velocity="3.2" />
        <dynamics damping="0.0" friction="0.0" />
    </joint>
    <link name="wrist_1_link">
        <visual>
            <geometry>
                <mesh filename="package://ur5_description/meshes/ur5/visual/wrist1.dae" />
            </geometry>
            <material name="LightGrey">
                <color rgba="0.7 0.7 0.7 1.0" />
            </material>
        </visual>
        <collision>
            <geometry>
                <mesh filename="package://ur5_description/meshes/ur5/collision/wrist1.stl" />
            </geometry>
        </collision>
        <inertial>
            <mass value="1.219" />
            <origin rpy="0 0 0" xyz="0.0 0.0 0.0" />
            <inertia ixx="0.11117275553087999" ixy="0.0" ixz="0.0" iyy="0.11117275553087999" iyz="0.0" izz="0.21942" />
        </inertial>
    </link>
    <joint name="wrist_2_joint" type="revolute">
        <parent link="wrist_1_link" />
        <child link="wrist_2_link" />
        <origin rpy="0.0 0.0 0.0" xyz="0.0 0.093 0.0" />
        <axis xyz="0 0 1" />
        <limit effort="28.0" lower="-3.141592653589793" upper="3.141592653589793" velocity="3.2" />
        <dynamics damping="0.0" friction="0.0" />
    </joint>
    <link name="wrist_2_link">
        <visual>
            <geometry>
                <mesh filename="package://ur5_description/meshes/ur5/visual/wrist2.dae" />
            </geometry>
            <material name="LightGrey">
                <color rgba="0.7 0.7 0.7 1.0" />
            </material>
        </visual>
        <collision>
            <geometry>
                <mesh filename="package://ur5_description/meshes/ur5/collision/wrist2.stl" />
            </geometry>
        </collision>
        <inertial>
            <mass value="1.219" />
            <origin rpy="0 0 0" xyz="0.0 0.0 0.0" />
            <inertia ixx="0.11117275553087999" ixy="0.0" ixz="0.0" iyy="0.11117275553087999" iyz="0.0" izz="0.21942" />
        </inertial>
    </link>
    <joint name="wrist_3_joint" type="revolute">
        <parent link="wrist_2_link" />
        <child link="wrist_3_link" />
        <origin rpy="0.0 0.0 0.0" xyz="0.0 0.0 0.09465" />
        <axis xyz="0 1 0" />
        <limit effort="28.0" lower="-3.141592653589793" upper="3.141592653589793" velocity="3.2" />
        <dynamics damping="0.0" friction="0.0" />
    </joint>
    <link name="wrist_3_link">
        <visual>
            <geometry>
                <mesh filename="package://ur5_description/meshes/ur5/visual/wrist3.dae" />
            </geometry>
            <material name="LightGrey">
                <color rgba="0.7 0.7 0.7 1.0" />
            </material>
        </visual>
        <collision>
            <geometry>
                <mesh filename="package://ur5_description/meshes/ur5/collision/wrist3.stl" />
            </geometry>
        </collision>
        <inertial>
            <mass value="0.1879" />
            <origin rpy="0 0 0" xyz="0.0 0.0 0.0" />
            <inertia ixx="0.017136473145408" ixy="0.0" ixz="0.0" iyy="0.017136473145408" iyz="0.0" izz="0.033822" />
        </inertial>
    </link>
    <joint name="ee_fixed_joint" type="fixed">
        <parent link="wrist_3_link" />
        <child link="ee_link" />
        <origin rpy="0.0 0.0 1.5707963267948966" xyz="0.0 0.0823 0.0" />
    </joint>
    <link name="ee_link">
        <collision>
            <geometry>
                <box size="0.01 0.01 0.01" />
            </geometry>
            <origin rpy="0 0 0" xyz="-0.01 0 0" />
        </collision>
        <inertial>
            <mass value="0.1" />
            <origin xyz="0 0 0" rpy="0 0 0" />
            <inertia ixx="0.03" iyy="0.03" izz="0.03" ixy="0.0" ixz="0.0" iyz="0.0" />
        </inertial>
    </link>
    <transmission name="trans_shoulder_pan_joint">
        <type>transmission_interface/SimpleTransmission</type>
        <joint name="shoulder_pan_joint">
            <hardwareInterface>hardware_interface/EffortJointInterface</hardwareInterface>
        </joint>
        <actuator name="shoulder_pan_joint_motor">
            <hardwareInterface>hardware_interface/EffortJointInterface</hardwareInterface>
            <mechanicalReduction>1</mechanicalReduction>
        </actuator>
    </transmission>
    <transmission name="trans_shoulder_lift_joint">
        <type>transmission_interface/SimpleTransmission</type>
        <joint name="shoulder_lift_joint">
            <hardwareInterface>hardware_interface/EffortJointInterface</hardwareInterface>
        </joint>
        <actuator name="shoulder_lift_joint_motor">
            <hardwareInterface>hardware_interface/EffortJointInterface</hardwareInterface>
            <mechanicalReduction>1</mechanicalReduction>
        </actuator>
    </transmission>
    <transmission name="trans_elbow_joint">
        <type>transmission_interface/SimpleTransmission</type>
        <joint name="elbow_joint">
            <hardwareInterface>hardware_interface/EffortJointInterface</hardwareInterface>
        </joint>
        <actuator name="elbow_joint_motor">
            <hardwareInterface>hardware_interface/EffortJointInterface</hardwareInterface>
            <mechanicalReduction>1</mechanicalReduction>
        </actuator>
    </transmission>
    <transmission name="trans_wrist_1_joint">
        <type>transmission_interface/SimpleTransmission</type>
        <joint name="wrist_1_joint">
            <hardwareInterface>hardware_interface/EffortJointInterface</hardwareInterface>
        </joint>
        <actuator name="wrist_1_joint_motor">
            <hardwareInterface>hardware_interface/EffortJointInterface</hardwareInterface>
            <mechanicalReduction>1</mechanicalReduction>
        </actuator>
    </transmission>
    <transmission name="trans_wrist_2_joint">
        <type>transmission_interface/SimpleTransmission</type>
        <joint name="wrist_2_joint">
            <hardwareInterface>hardware_interface/EffortJointInterface</hardwareInterface>
        </joint>
        <actuator name="wrist_2_joint_motor">
            <hardwareInterface>hardware_interface/EffortJointInterface</hardwareInterface>
            <mechanicalReduction>1</mechanicalReduction>
        </actuator>
    </transmission>
    <transmission name="trans_wrist_3_joint">
        <type>transmission_interface/SimpleTransmission</type>
        <joint name="wrist_3_joint">
            <hardwareInterface>hardware_interface/EffortJointInterface</hardwareInterface>
        </joint>
        <actuator name="wrist_3_joint_motor">
            <hardwareInterface>hardware_interface/EffortJointInterface</hardwareInterface>
            <mechanicalReduction>1</mechanicalReduction>
        </actuator>
    </transmission>
    <gazebo>
        <plugin name="gazebo_ros_control" filename="libgazebo_ros_control.so">
            <robotNamespace>/</robotNamespace>
        </plugin>
    </gazebo>
</robot>

